Workbook

Sheet COVER
B2: ASSERIS · Kantor Akuntan Publik
B3: Registered Public Accountants
B5: KERTAS KERJA AUDIT (KKA)
B6: Audit Working Paper File — Audit Laporan Keuangan
B9: Nama Klien | C9: PT Sentosa Makmur Tbk
B10: NPWP | C10: 01.234.567.8-045.000
B11: Perikatan / Engagement | C11: ENG-2025-014
B12: Periode Audit | C12: Tahun Buku Berakhir 31 Desember 2025
B13: Kerangka Pelaporan | C13: SAK (PSAK) — ISA-converged (SA / SPAP)
B14: Jenis Perikatan | C14: Audit Laporan Keuangan Statutory
B15: Partner Penanggung Jawab | C15: Hartono Wijaya, CPA
B16: Manajer Audit | C16: Anindya Pramesti, CPA
B17: Auditor Senior | C17: Dimas Raharja
B18: Tanggal Mulai | C18: ____ / ____ / 20__
B19: Tanggal Selesai (Laporan) | C19: ____ / ____ / 20__
B20: Status File | C20: ☐ Draft ☐ Direviu ☐ Final/Arsip (locked)
B22: CATATAN KERAHASIAAN
B23: File ini rahasia, milik KAP, disusun sesuai SA 230 (Dokumentasi Audit). Akses terbatas pada tim perikatan, reviewer berjenjang (Senior → Manajer → Partner), EQR, dan inspeksi mutu. Lock & arsip dalam 60 hari setelah tanggal laporan (ISQM 1).
B27: ➜ Buka Daftar Indeks KKA (INDEX)

Sheet INDEX KKA
A1: ASSERIS · Kantor Akuntan Publik
A2: Registered Public Accountants · Izin Usaha KAP No. ___/KM.1/20__ · Anggota IAPI · www.asseris.co.id
A4: PT Sentosa Makmur Tbk — Tahun Buku Berakhir 31 Desember 2025
A5: DAFTAR INDEKS KERTAS KERJA
A6: Indeks KKA: INDEX · Standar: SA 230 · Fase: Semua
A7: Peta seluruh KKA mengikuti siklus audit Fase 0–5 (Asseris). Klik Ref untuk membuka sheet.
A9: Ref | B9: Nama Kertas Kerja | C9: Fase | D9: Standar SA | E9: Status | F9: Disusun | G9: Direviu | H9: Disetujui
A10: COVER | B10: Sampul & Identitas Perikatan | C10: — | D10: SA 230 | E10: Final | F10: DR | G10: AP | H10: HW
A11: A0 | B11: Penerimaan & Keberlanjutan | C11: 0 · Acceptance | D11: SA 220 · ISQM 1 · SA 210 | E11: Selesai | F11: DR | G11: AP | H11: HW
A12: IND | B12: Independensi & Etika Profesi | C12: 0 · Acceptance | D12: SA 220 · Kode Etik | E12: Selesai | F12: DR | G12: AP | H12: HW
A13: P0 | B13: Pemahaman Entitas & Lingkungan | C13: 1 · Planning | D13: SA 315 | E13: Selesai | F13: DR | G13: AP | H13: HW
A14: P1 | B14: Materialitas | C14: 1 · Planning | D14: SA 320 | E14: Selesai | F14: DR | G14: AP | H14: HW
A15: P2 | B15: Penilaian Risiko & Respons | C15: 1 · Planning | D15: SA 315 · SA 330 · SA 240 | E15: Selesai | F15: DR | G15: AP | H15: HW
A16: ICFR | B16: Pengendalian Internal & Walkthrough | C16: 1 · Planning | D16: SA 315 · SA 330 | E16: Selesai | F16: DR | G16: AP | H16: HW
A17: P3 | B17: Strategi Audit & Program | C17: 1 · Planning | D17: SA 300 | E17: Selesai | F17: DR | G17: AP | H17: HW
A18: WTB | B18: Working Trial Balance (Lead utama) | C18: 2 · Fieldwork | D18: SA 230 · SA 330 | E18: Berjalan | F18: DR | G18: AP
A19: AJE | B19: Jurnal Penyesuaian & Reklas | C19: 2 · Fieldwork | D19: SA 450 | E19: Berjalan | F19: DR | G19: AP
A20: A | B20: Kas & Setara Kas | C20: 2 · Fieldwork | D20: SA 500 · SA 505 | E20: Berjalan | F20: DR | G20: AP
A21: B | B21: Piutang Usaha & CKPN | C21: 2 · Fieldwork | D21: SA 505 · SA 540 · PSAK 71 | E21: Berjalan | F21: DR | G21: AP
A22: C | B22: Persediaan | C22: 2 · Fieldwork | D22: SA 501 | E22: Berjalan | F22: DR | G22: AP
A23: D | B23: Aset Tetap & Takberwujud | C23: 2 · Fieldwork | D23: SA 500 · PSAK 16/19 | E23: Berjalan | F23: DR | G23: AP
A24: E | B24: Sewa (Hak-Guna, PSAK 73) | C24: 2 · Fieldwork | D24: SA 540 · PSAK 73 | E24: Berjalan | F24: DR | G24: AP
A25: F | B25: Utang Usaha & Akrual | C25: 2 · Fieldwork | D25: SA 505 · SUL | E25: Berjalan | F25: DR | G25: AP
A26: G | B26: Utang Bank & Pinjaman | C26: 2 · Fieldwork | D26: SA 505 | E26: Berjalan | F26: DR | G26: AP
A27: H | B27: Perpajakan | C27: 2 · Fieldwork | D27: PSAK 46 · SA 250 | E27: Berjalan | F27: DR | G27: AP
A28: I | B28: Imbalan Kerja | C28: 2 · Fieldwork | D28: SA 540 · PSAK 24 | E28: Berjalan | F28: DR | G28: AP
A29: J | B29: Ekuitas | C29: 2 · Fieldwork | D29: SA 500 | E29: Berjalan | F29: DR | G29: AP
... A45: ARCH | B45: Penyelesaian & Pengarsipan | C45: 5 · Archive | D45: SA 230 · ISQM 1 | E45: Belum | F45: DR | G45: AP
A46: REF | B46: Peta Standar SA per Fase | C46: — | D46: SA (SPAP) | E46: Ref | F46: — | G46: — | H46: —
A48: Legenda: | B48: DR=Dimas Raharja (Senior) · AP=Anindya Pramesti (Manajer) · HW=Hartono Wijaya (Partner). Status: Selesai=kesimpulan ditandatangani; Berjalan=fieldwork; Belum=menunggu gate fase.

Sheet A0 - Acceptance
A1: ASSERIS · Kantor Akuntan Publik
A2: Registered Public Accountants · Izin Usaha KAP No. ___/KM.1/20__ · Anggota IAPI · www.asseris.co.id
A4: PT Sentosa Makmur Tbk — Tahun Buku Berakhir 31 Desember 2025
A5: PENERIMAAN & KEBERLANJUTAN PERIKATAN
A6: Indeks KKA: A0 · Standar: SA 220 · ISQM 1 · SA 210 · Fase: 0 · Acceptance | H6: ↩ Index
A7: Gate Fase 0 → 1: wajib selesai sebelum Surat Perikatan (SA 210). Independensi tim dikonfirmasi (SA 220 · ISQM 1).
A9: No | B9: Kriteria Penilaian | C9: Ya | D9: Tidak | E9: Catatan / Bukti
A10: 1 | B10: Integritas manajemen & pemilik dapat diandalkan (tidak ada red flag fraud). | C10: ☐ | D10: ☐
A11: 2 | B11: Tidak ada ancaman independensi yang tak dapat dikurangi ke tingkat dapat diterima. | C11: ☐ | D11: ☐
A12: 3 | B12: KAP memiliki kompetensi, waktu, dan sumber daya untuk perikatan ini. | C12: ☐ | D12: ☐
A13: 4 | B13: Tidak ada konflik kepentingan dengan klien lain. | C13: ☐ | D13: ☐
A14: 5 | B14: Kelengkapan PMPJ/AML (KYC) klien terpenuhi. | C14: ☐ | D14: ☐
A15: 6 | B15: Continuance: tidak ada perselisihan signifikan / scope limitation periode lalu. | C15: ☐ | D15: ☐
A16: 7 | B16: Fee sepadan dengan risiko & lingkup (tidak menimbulkan ancaman self-interest). | C16: ☐ | D16: ☐
A17: 8 | B17: Komunikasi dengan auditor pendahulu dilakukan (jika klien baru) — SA 510. | C17: ☐ | D17: ☐
A19: KEPUTUSAN PENERIMAAN/KEBERLANJUTAN
A20: ☐ Diterima / Dilanjutkan ☐ Diterima dengan syarat ☐ Ditolak
A22: Disusun oleh | B22: Dimas Raharja | C22: Tgl: | D22: ______ | E22: Direviu oleh | F22: Anindya Pramesti, CPA | G22: Tgl: | H22: ______
A23: Disetujui Partner | B23: Hartono Wijaya, CPA | C23: Tgl: | D23: ______

Sheet IND - Independensi
A1: ASSERIS · Kantor Akuntan Publik
A2: Registered Public Accountants · Izin Usaha KAP No. ___/KM.1/20__ · Anggota IAPI · www.asseris.co.id
A4: PT Sentosa Makmur Tbk — Tahun Buku Berakhir 31 Desember 2025
A5: INDEPENDENSI & ETIKA PROFESI
A6: Indeks KKA: IND · Standar: SA 220 · Kode Etik · Fase: 0 · Acceptance | E6: ↩ Index
A7: Pernyataan & evaluasi ancaman independensi seluruh anggota tim (SA 220 · Kode Etik IAPI).
A9: No | B9: Uraian / Kriteria | C9: Ya/Ada | D9: Tidak | E9: Catatan / Ref WP
A10: 1 | B10: Seluruh anggota tim menandatangani pernyataan independensi tahunan. | C10: ☐ | D10: ☐
A11: 2 | B11: Tidak ada kepentingan keuangan langsung/tidak langsung pada klien. | C11: ☐ | D11: ☐
A12: 3 | B12: Tidak ada hubungan keluarga dekat dengan manajemen kunci/pemilik. | C12: ☐ | D12: ☐
A13: 4 | B13: Tidak ada jasa non-asurans yang menimbulkan ancaman self-review. | C13: ☐ | D13: ☐
A14: 5 | B14: Rotasi partner & EQR dipatuhi (untuk entitas kepentingan publik). | C14: ☐ | D14: ☐
A15: 6 | B15: Tingkat fee tidak menciptakan ancaman self-interest (ketergantungan). | C15: ☐ | D15: ☐
A16: 7 | B16: Lima ancaman dinilai (self-interest, self-review, advokasi, kedekatan, intimidasi) & pengaman diterapkan. | C16: ☐ | D16: ☐
A17: 8 | B17: Konfirmasi independensi tingkat KAP (firm-wide) diperoleh. | C17: ☐ | D17: ☐
A19: KESIMPULAN
A20: [Tuliskan kesimpulan, isu terbuka & tindak lanjut.]
A23: Disusun oleh | B23: Dimas Raharja | C23: Tgl: | D23: ______ | E23: Direviu oleh | F23: Anindya Pramesti, CPA | G23: Tgl: | H23: ______
A24: Disetujui Partner | B24: Hartono Wijaya, CPA | C24: Tgl: | D24: ______

Sheet P0 - Pemahaman Entitas
A1: ASSERIS · Kantor Akuntan Publik
A2: Registered Public Accountants · Izin Usaha KAP No. ___/KM.1/20__ · Anggota IAPI · www.asseris.co.id
A4: PT Sentosa Makmur Tbk — Tahun Buku Berakhir 31 Desember 2025
A5: PEMAHAMAN ENTITAS & LINGKUNGANNYA
A6: Indeks KKA: P0 · Standar: SA 315 · Fase: 1 · Planning | E6: ↩ Index
A7: Dasar identifikasi risiko salah saji material (SA 315) & diskusi tim perikatan.
A9: No | B9: Uraian / Kriteria | C9: Ya/Ada | D9: Tidak | E9: Catatan / Ref WP
A10: 1 | B10: Model bisnis, industri, & faktor eksternal (regulasi, pasar) dipahami & didokumentasikan. | C10: ☐ | D10: ☐
A11: 2 | B11: Struktur kepemilikan, tata kelola, & daftar pihak berelasi diidentifikasi. | C11: ☐ | D11: ☐
A12: 3 | B12: Kerangka pelaporan & kebijakan akuntansi signifikan dipahami. | C12: ☐ | D12: ☐
A13: 4 | B13: Lingkungan TI & sistem informasi relevan pelaporan keuangan dipetakan. | C13: ☐ | D13: ☐
A14: 5 | B14: Pengendalian tingkat entitas (control environment) dievaluasi. | C14: ☐ | D14: ☐
A15: 6 | B15: Estimasi akuntansi signifikan & area judgment diidentifikasi. | C15: ☐ | D15: ☐
A16: 7 | B16: Prosedur analitis awal untuk identifikasi risiko dilakukan. | C16: ☐ | D16: ☐
A17: 8 | B17: Diskusi tim perikatan atas kerentanan salah saji & fraud terdokumentasi (SA 240.15). | C17: ☐ | D17: ☐
A19: KESIMPULAN
A20: [Tuliskan kesimpulan, isu terbuka & tindak lanjut.]
A23: Disusun oleh | B23: Dimas Raharja | C23: Tgl: | D23: ______ | E23: Direviu oleh | F23: Anindya Pramesti, CPA | G23: Tgl: | H23: ______
A24: Disetujui Partner | B24: Hartono Wijaya, CPA | C24: Tgl: | D24: ______

Sheet P1 - Materialitas
A1: ASSERIS · Kantor Akuntan Publik
A2: Registered Public Accountants · Izin Usaha KAP No. ___/KM.1/20__ · Anggota IAPI · www.asseris.co.id
A4: PT Sentosa Makmur Tbk — Tahun Buku Berakhir 31 Desember 2025
A5: PENETAPAN MATERIALITAS
A6: Indeks KKA: P1 · Standar: SA 320 · Fase: 1 · Planning | H6: ↩ Index
A7: Ditetapkan pada Fase Planning (SA 320). Basis & nilai dari TB klien. Angka final disetujui Partner.
A9: Perhitungan materialitas
B10: Komponen | C10: Nilai | D10: Sumber/Dasar
B11: Basis terpilih | C11: Pendapatan (Penjualan Bersih) | D11: WTB 4-1100
B12: Nilai basis (Rp) | C12: 331900000000 | D12: WTB Saldo Audit
B13: Persentase basis (%) | C13: 0.0075 | D13: Judgment 0,5–1%
B14: Overall Materiality (OM) | C14: =C12*C13 -> 2489250000 | D14: nilai × %
B15: Performance Materiality % | C15: 0.65 | D15: 50–75%
B16: Performance Materiality (PM) | C16: =C14*C15 -> 1618012500 | D16: OM × %
B17: Clearly Trivial % | C17: 0.05 | D17: ~5% dari OM
B18: Clearly Trivial Threshold | C18: =C14*C17 -> 124462500 | D18: < ini tidak diakumulasi
A20: Dasar pemilihan basis
A21: Entitas berorientasi laba; pengguna utama pemegang saham & kreditur. Pendapatan dipilih karena paling stabil & relevan. PM 65% mempertimbangkan risiko signifikan pengakuan pendapatan (SA 240) & estimasi CKPN.
A24: Disusun oleh | B24: Dimas Raharja | C24: Tgl: | D24: ______ | E24: Direviu oleh | F24: Anindya Pramesti, CPA | G24: Tgl: | H24: ______
A25: Disetujui Partner | B25: Hartono Wijaya, CPA | C25: Tgl: | D25: ______

Sheet P2 - Risiko
A1: ASSERIS · Kantor Akuntan Publik
A2: Registered Public Accountants · Izin Usaha KAP No. ___/KM.1/20__ · Anggota IAPI · www.asseris.co.id
A4: PT Sentosa Makmur Tbk — Tahun Buku Berakhir 31 Desember 2025
A5: PENILAIAN RISIKO & RESPONS
A6: Indeks KKA: P2 · Standar: SA 315 · SA 330 · SA 240 · Fase: 1 · Planning | J6: ↩ Index
A7: Identifikasi RSSM tingkat asersi (SA 315) & rancangan respons (SA 330). Pengakuan pendapatan = risiko fraud default (SA 240).
A9: ID | B9: Area | C9: Asersi | D9: Deskripsi Risiko | E9: L | F9: I | G9: Inheren | H9: Respons Audit | I9: Fraud | J9: WP
A10: R-01 | B10: Pendapatan | C10: Occurrence | D10: Pengakuan pendapatan dipercepat/fiktif menjelang tutup buku | E10: 4 | F10: 5 | G10: Signifikan | H10: Cut-off testing, vouching pengiriman & kontrak (PSAK 72), uji jurnal | I10: Ya | J10: K/JET
A11: R-02 | B11: Persediaan | C11: Valuation | D11: Persediaan usang tidak dicadangkan; NRV < biaya | E11: 3 | F11: 4 | G11: Signifikan | H11: Uji NRV, observasi stock opname & test count (SA 501) | I11: Tidak | J11: C
A12: R-03 | B12: Piutang Usaha | C12: Valuation | D12: Estimasi ECL/CKPN (PSAK 71) tidak memadai | E12: 4 | F12: 4 | G12: Signifikan | H12: Re-perform model ECL, uji aging & subsequent collection | I12: Tidak | J12: B
A13: R-04 | B13: Aset Tetap | C13: Existence | D13: Aset dilepas namun masih tercatat | E13: 2 | F13: 3 | G13: Moderat | H13: Vouching penambahan/pelepasan, inspeksi fisik, rekon FAR | I13: Tidak | J13: D
A14: R-05 | B14: Beban Akrual | C14: Completeness | D14: Liabilitas/akrual tidak dicatat (understatement) | E14: 3 | F14: 4 | G14: Signifikan | H14: Search for unrecorded liabilities, uji subsequent payment | I14: Tidak | J14: F
A15: R-06 | B15: Perpajakan | C15: Accuracy | D15: Rekonsiliasi fiskal & pajak tangguhan keliru (PSAK 46) | E15: 3 | F15: 3 | G15: Moderat | H15: Tie-out SPT, re-compute deferred tax, telaah sengketa | I15: Tidak | J15: H
A16: R-07 | B16: Sewa | C16: Measurement | D16: Pengukuran aset hak-guna & liabilitas sewa (PSAK 73) | E16: 2 | F16: 3 | G16: Moderat | H16: Re-compute discount rate & amortisasi, telaah kontrak | I16: Tidak | J16: E
A18: Skala: | B18: L=Likelihood (1–5), I=Impact (1–5). Inheren Signifikan bila kombinasi tinggi atau risiko fraud. Tiap risiko signifikan wajib punya respons substantif spesifik (SA 330).

Sheet ICFR - Pengendalian Internal
A1: ASSERIS · Kantor Akuntan Publik
A2: Registered Public Accountants · Izin Usaha KAP No. ___/KM.1/20__ · Anggota IAPI · www.asseris.co.id
A4: PT Sentosa Makmur Tbk — Tahun Buku Berakhir 31 Desember 2025
A5: PENGENDALIAN INTERNAL & WALKTHROUGH
A6: Indeks KKA: ICFR · Standar: SA 315 · SA 330 · Fase: 1 · Planning | E6: ↩ Index
A7: Pemahaman & pengujian rancangan/implementasi pengendalian per siklus (SA 315 · SA 330).
A9: Kolom Ya = kontrol dirancang & diimplementasikan efektif; Tidak = defisiensi (lanjutkan ke SA 265).
A10: No | B10: Uraian / Kriteria | C10: Ya/Ada | D10: Tidak | E10: Catatan / Ref WP
A11: 1 | B11: Siklus Pendapatan–Piutang–Penerimaan: walkthrough & kontrol kunci teridentifikasi. | C11: ☐ | D11: ☐
A12: 2 | B12: Siklus Pembelian–Utang–Pengeluaran: walkthrough & kontrol kunci. | C12: ☐ | D12: ☐
A13: 3 | B13: Siklus Persediaan & Produksi: walkthrough & kontrol kunci. | C13: ☐ | D13: ☐
A14: 4 | B14: Siklus Penggajian & SDM: walkthrough & kontrol kunci. | C14: ☐ | D14: ☐
A15: 5 | B15: Proses pelaporan keuangan & jurnal period-end: kontrol kunci. | C15: ☐ | D15: ☐
A16: 6 | B16: ITGC (akses, perubahan program, operasi TI) dinilai. | C16: ☐ | D16: ☐
A17: 7 | B17: Rancangan & implementasi kontrol kunci diuji (D&I). | C17: ☐ | D17: ☐
A18: 8 | B18: Keputusan: mengandalkan pengendalian? (Ya → uji pengendalian; Tidak → substantif penuh). | C18: ☐ | D18: ☐
A20: KESIMPULAN
A21: [Tuliskan kesimpulan, isu terbuka & tindak lanjut.]
A24: Disusun oleh | B24: Dimas Raharja | C24: Tgl: | D24: ______ | E24: Direviu oleh | F24: Anindya Pramesti, CPA | G24: Tgl: | H24: ______
A25: Disetujui Partner | B25: Hartono Wijaya, CPA | C25: Tgl: | D25: ______

Sheet P3 - Program
A1: ASSERIS · Kantor Akuntan Publik
A2: Registered Public Accountants · Izin Usaha KAP No. ___/KM.1/20__ · Anggota IAPI · www.asseris.co.id
A4: PT Sentosa Makmur Tbk — Tahun Buku Berakhir 31 Desember 2025
A5: STRATEGI AUDIT & PROGRAM (MASTER)
A6: Indeks KKA: P3 · Standar: SA 300 · Fase: 1 · Planning | H6: ↩ Index
A7: Strategi keseluruhan & arah program (SA 300). Program per area dirinci di lead schedule.
A9: RINGKASAN STRATEGI
A10: Pendekatan audit | C10: Kombinasi uji pengendalian terbatas + substantif; substantif penuh untuk area risiko signifikan.
A11: Area fokus | C11: Pendapatan (fraud), CKPN/ECL, Persediaan (NRV & opname), Sewa PSAK 73, Perpajakan.
A12: Penggunaan ahli | C12: Aktuaris (imbalan kerja PSAK 24); penilai (bila ada revaluasi).
A13: Komponen/Group | C13: Entitas tunggal — tidak ada komponen signifikan (SA 600 n/a).
A14: Tim & jadwal | C14: Partner HW, Manajer AP, Senior DR + 2 staf; fieldwork Feb–Mar, pelaporan Mar.
A15: Materialitas | C15: OM, PM, trivial mengikuti KKA P1 (SA 320).
A17: PROGRAM AUDIT — 29 LANGKAH → 6 FASE
A18: # | B18: Prosedur / Tahapan | C18: Fase | D18: SA | E18: Status | F18: WP | G18: Oleh
A19: 1 | B19: Penerimaan & keberlanjutan + independensi | C19: 0 | D19: SA 220 | E19: Selesai | F19: A0 | G19: AP
A20: 2 | B20: Surat perikatan ditandatangani | C20: 0 | D20: SA 210 | E20: Selesai | F20: A0 | G20: HW
A21: 3 | B21: Pemahaman entitas & lingkungannya | C21: 1 | D21: SA 315 | E21: Selesai | F21: P2 | G21: DR
A22: 4 | B22: Penilaian risiko tingkat asersi | C22: 1 | D22: SA 315 | E22: Selesai | F22: P2 | G22: AP
A23: 5 | B23: Penetapan materialitas | C23: 1 | D23: SA 320 | E23: Selesai | F23: P1 | G23: AP
A24: 6 | B24: Strategi & rencana audit disetujui partner | C24: 1 | D24: SA 300 | E24: Selesai | F24: P3 | G24: HW
A25: 7 | B25: Prosedur analitis pendahuluan | C25: 1 | D25: SA 520 | E25: Selesai | F25: AR | G25: DR
A26: 8 | B26: Evaluasi going concern awal | C26: 1 | D26: SA 570 | E26: Selesai | F26: GC | G26: AP
A27: 9–20 | B27: Prosedur substantif per area A–K | C27: 2 | D27: SA 330/500 | E27: Berjalan | F27: A–K | G27: DR
A28: 21 | B28: Tindak lanjut open issues | C28: 2 | D28: SA 230 | E28: Berjalan | F28: WTB | G28: AP
A29: 22 | B29: Review berjenjang Senior→Manajer | C29: 3 | D29: SA 220 | E29: Belum | F29: — | G29: AP
... A36: 29 | B36: Penyelesaian & arsip file (lock 60 hari) | C36: 5 | D36: SA 230 | E36: Belum | F36: — | G36: AP

Sheet WTB
A1: ASSERIS · Kantor Akuntan Publik
A2: Registered Public Accountants · Izin Usaha KAP No. ___/KM.1/20__ · Anggota IAPI · www.asseris.co.id
A4: PT Sentosa Makmur Tbk — Tahun Buku Berakhir 31 Desember 2025
A5: WORKING TRIAL BALANCE
A6: Indeks KKA: WTB · Standar: SA 230 · SA 330 · Fase: 2 · Fieldwork | H6: ↩ Index
A7: Lead schedule utama (SSOT). Saldo Audit = Per Klien + AJE. Kolom Lead menautkan akun ke KKA area.
A9: Klasifikasi | B9: Kode | C9: Nama Akun | D9: Saldo TL (Audited) | E9: Per Klien (Unadj) | F9: AJE | G9: Saldo Audit (Adj) | H9: Lead
A10: Aset Lancar | B10: 1-1100 | C10: Kas dan Setara Kas | D10: 18420500000 | E10: 21905300000 | F10: 0 | G10: =E10+F10 -> 21905300000 | H10: A
A11: Aset Lancar | B11: 1-1200 | C11: Piutang Usaha - Pihak Ketiga | D11: 42180900000 | E11: 51322400000 | F11: -1850000000 | G11: =E11+F11 -> 49472400000 | H11: B
A12: Aset Lancar | B12: 1-1210 | C12: Cadangan Kerugian Penurunan Nilai | D12: -2109000000 | E12: -1980000000 | F12: -620000000 | G12: =E12+F12 -> -2600000000 | H12: B
A13: Aset Lancar | B13: 1-1300 | C13: Persediaan | D13: 64550200000 | E13: 78904100000 | F13: -2340000000 | G13: =E13+F13 -> 76564100000 | H13: C
A14: Aset Lancar | B14: 1-1400 | C14: Pajak Dibayar di Muka | D14: 3902100000 | E14: 4551800000 | F14: 0 | G14: =E14+F14 -> 4551800000 | H14: H
A15: Aset Lancar | B15: 1-1500 | C15: Biaya Dibayar di Muka | D15: 1780400000 | E15: 2104600000 | F15: 0 | G15: =E15+F15 -> 2104600000 | H15: D
A16: Aset Tidak Lancar | B16: 1-2100 | C16: Aset Tetap - Harga Perolehan | D16: 183209000000 | E16: 200339700000 | F16: 0 | G16: =E16+F16 -> 200339700000 | H16: D
A17: Aset Tidak Lancar | B17: 1-2110 | C17: Akumulasi Penyusutan | D17: -50860000000 | E17: -57180000000 | F17: -1120000000 | G17: =E17+F17 -> -58300000000 | H17: D
A18: Aset Tidak Lancar | B18: 1-2400 | C18: Aset Takberwujud - Harga Perolehan | D18: 8400000000 | E18: 9600000000 | F18: 0 | G18: =E18+F18 -> 9600000000 | H18: D
A19: Aset Tidak Lancar | B19: 1-2410 | C19: Akumulasi Amortisasi | D19: -3360000000 | E19: -4700000000 | F19: 0 | G19: =E19+F19 -> -4700000000 | H19: D
A20: Aset Tidak Lancar | B20: 1-2300 | C20: Aset Hak-Guna (PSAK 73) | D20: 0 | E20: 12640000000 | F20: 0 | G20: =E20+F20 -> 12640000000 | H20: E
A21: Aset Tidak Lancar | B21: 1-2500 | C21: Aset Pajak Tangguhan | D21: 4110000000 | E21: 4980000000 | F21: 470000000 | G21: =E21+F21 -> 5450000000 | H21: H
... A37: Beban | B37: 5-5100 | C37: Beban Pajak Penghasilan | D37: 9180000000 | E37: 11240000000 | F37: -470000000 | G37: =E37+F37 -> 10770000000 | H37: H
C38: Jumlah (Σ) | D38: =SUM(D10:D37) -> -15510000000 | E38: =SUM(E10:E37) -> -11540000000 | F38: =SUM(F10:F37) -> 0 | G38: =SUM(G10:G37) -> -11540000000
C39: Kontrol AJE — Σ penyesuaian (harus 0) | F39: =SUM(F10:F37) -> 0 | H39: =IF(ROUND(F39,0)=0,"SEIMBANG","PERIKSA") -> SEIMBANG
A41: Catatan: | B41: Kolom biru = input (TB klien & TL audited). Saldo Audit & seluruh subtotal dihitung formula. Kontrol AJE (baris 39) harus 0 — total debit penyesuaian = total kredit. Pada TB klien lengkap, Σ saldo Adj juga = 0. AJE bersumber dari KKA 'AJE'.

Sheet AJE
A1: ASSERIS · Kantor Akuntan Publik
A2: Registered Public Accountants · Izin Usaha KAP No. ___/KM.1/20__ · Anggota IAPI · www.asseris.co.id
A4: PT Sentosa Makmur Tbk — Tahun Buku Berakhir 31 Desember 2025
A5: JURNAL PENYESUAIAN & REKLASIFIKASI
A6: Indeks KKA: AJE · Standar: SA 450 · Fase: 2 · Fieldwork | H6: ↩ Index
A7: Usulan & posting penyesuaian audit (SA 450). Proposed=diusulkan; Posted=disetujui klien.
A9: ID | B9: Deskripsi | C9: WP | D9: Status | E9: Debit (akun) | F9: Kredit (akun) | G9: Nilai (Rp) | H9: Tipe
A10: AJE-01 | B10: Penyesuaian cut-off persediaan akhir | C10: C-3 | D10: Posted | E10: 5-1100 BPP | F10: 1-1300 Persediaan | G10: 2340000000 | H10: Koreksi
A11: AJE-02 | B11: Tambahan CKPN piutang (model ECL) | C11: B-7 | D11: Posted | E11: 5-3100 Beban Umum | F11: 1-1210 CKPN | G11: 620000000 | H11: Koreksi
A12: AJE-03 | B12: Pembalikan piutang fiktif (cut-off) | C12: B-2 | D12: Proposed | E12: 4-1100 Penjualan | F12: 1-1200 Piutang | G12: 1850000000 | H12: Koreksi
A13: AJE-04 | B13: Akrual bonus manajemen | C13: F-1 | D13: Posted | E13: 5-3100 Beban Umum | F13: 2-1300 Akrual | G13: 980000000 | H13: Koreksi
A14: AJE-05 | B14: Penyusutan tambahan aset tetap | C14: D-2 | D14: Posted | E14: 5-3100 Beban Umum | F14: 1-2110 Ak. Penyusutan | G14: 1120000000 | H14: Koreksi
A15: AJE-06 | B15: Pajak tangguhan atas penyesuaian | C15: H-1 | D15: Proposed | E15: 1-2500 Aset Pajak Tgh | F15: 5-5100 Beban Pajak | G15: 470000000 | H15: Koreksi
B16: Total nilai penyesuaian | G16: =SUM(G10:G15) -> 7380000000
A18: Disusun oleh | B18: Dimas Raharja | C18: Tgl: | D18: ______ | E18: Direviu oleh | F18: Anindya Pramesti, CPA | G18: Tgl: | H18: ______
A19: Disetujui Partner | B19: Hartono Wijaya, CPA | C19: Tgl: | D19: ______

Sheet A - Kas & Setara Kas
A1: ASSERIS · Kantor Akuntan Publik
A2: Registered Public Accountants · Izin Usaha KAP No. ___/KM.1/20__ · Anggota IAPI · www.asseris.co.id
A4: PT Sentosa Makmur Tbk — Tahun Buku Berakhir 31 Desember 2025
A5: LEAD SCHEDULE A — Kas & Setara Kas
A6: Indeks KKA: A · Standar: SA 500 · SA 505 · Fase: 2 · Fieldwork | H6: ↩ Index
A7: Saldo per akun tertaut ke WTB. Program prosedur & kesimpulan area mengikuti SA/PSAK terkait.
A9: Kode | B9: Nama Akun | C9: Saldo TL | D9: Per Klien | E9: AJE | F9: Saldo Audit | G9: Saldo / PM | H9: Ref
A10: 1-1100 | B10: Kas dan Setara Kas | C10: =WTB!D10 -> 18420500000 | D10: =WTB!E10 -> 21905300000 | E10: =WTB!F10 -> 0 | F10: =WTB!G10 -> 21905300000 | G10: =IF('P1 - Materialitas'!C16=0,0,ABS(F10)/'P1 - Materialitas'!C16) -> 13.5384 | H10: A-1
B11: Total area | C11: =SUM(C10) -> 18420500000 | D11: =SUM(D10) -> 21905300000 | E11: =SUM(E10) -> 0 | F11: =SUM(F10) -> 21905300000 | G11: =IF('P1 - Materialitas'!C16=0,0,ABS(F11)/'P1 - Materialitas'!C16) -> 13.5384
A13: PROGRAM PROSEDUR AUDIT
A14: # | B14: Prosedur | C14: Asersi | D14: ✓ | E14: Hasil / Ref Bukti
A15: 1 | B15: Peroleh & uji rekonsiliasi bank tiap rekening; telusuri rekonsiliasi item. | C15: C/E/A | D15: ☐
A16: 2 | B16: Kirim & kendalikan konfirmasi bank (SA 505); cocokkan saldo & fasilitas. | C16: V/E | D16: ☐
A17: 3 | B17: Cash count kas kecil pada/dekat tanggal neraca. | C17: A/V | D17: ☐
A18: 4 | B18: Uji cut-off transfer antar-rekening (window dressing). | C18: C/E | D18: ☐
A19: 5 | B19: Telaah klasifikasi setara kas (jatuh tempo ≤ 3 bulan). | C19: P&D | D19: ☐
A21: KESIMPULAN AREA
A22: Berdasarkan prosedur di atas, saldo akun area ini disajikan wajar dalam semua hal material sesuai kerangka pelaporan; salah saji teridentifikasi dicatat di 'AJE' & direkap di 'SAD'. [Tuliskan kesimpulan & isu terbuka spesifik.]
A25: Disusun oleh | B25: Dimas Raharja | C25: Tgl: | D25: ______ | E25: Direviu oleh | F25: Anindya Pramesti, CPA | G25: Tgl: | H25: ______
A26: Disetujui Partner | B26: Hartono Wijaya, CPA | C26: Tgl: | D26: ______

Sheet B - Piutang Usaha & CKPN
A1: ASSERIS · Kantor Akuntan Publik
A2: Registered Public Accountants · Izin Usaha KAP No. ___/KM.1/20__ · Anggota IAPI · www.asseris.co.id
A4: PT Sentosa Makmur Tbk — Tahun Buku Berakhir 31 Desember 2025
A5: LEAD SCHEDULE B — Piutang Usaha & CKPN
A6: Indeks KKA: B · Standar: SA 505 · SA 540 · PSAK 71 · Fase: 2 · Fieldwork | H6: ↩ Index
A7: Saldo per akun tertaut ke WTB. Program prosedur & kesimpulan area mengikuti SA/PSAK terkait.
A9: Kode | B9: Nama Akun | C9: Saldo TL | D9: Per Klien | E9: AJE | F9: Saldo Audit | G9: Saldo / PM | H9: Ref
A10: 1-1200 | B10: Piutang Usaha - Pihak Ketiga | C10: =WTB!D11 -> 42180900000 | D10: =WTB!E11 -> 51322400000 | E10: =WTB!F11 -> -1850000000 | F10: =WTB!G11 -> 49472400000 | G10: =IF('P1 - Materialitas'!C16=0,0,ABS(F10)/'P1 - Materialitas'!C16) -> 30.576031 | H10: B-1
A11: 1-1210 | B11: Cadangan Kerugian Penurunan Nilai | C11: =WTB!D12 -> -2109000000 | D11: =WTB!E12 -> -1980000000 | E11: =WTB!F12 -> -620000000 | F11: =WTB!G12 -> -2600000000 | G11: =IF('P1 - Materialitas'!C16=0,0,ABS(F11)/'P1 - Materialitas'!C16) -> 1.6069097 | H11: B-2
B12: Total area | C12: =SUM(C10:C11) -> 40071900000 | D12: =SUM(D10:D11) -> 49342400000 | E12: =SUM(E10:E11) -> -2470000000 | F12: =SUM(F10:F11) -> 46872400000 | G12: =IF('P1 - Materialitas'!C16=0,0,ABS(F12)/'P1 - Materialitas'!C16) -> 28.969121
A14: PROGRAM PROSEDUR AUDIT
A15: # | B15: Prosedur | C15: Asersi | D15: ✓ | E15: Hasil / Ref Bukti
A16: 1 | B16: Susun aging schedule & cocokkan ke buku besar. | C16: C/E/A | D16: ☐
A17: 2 | B17: Konfirmasi positif sampel piutang (SA 505); prosedur alternatif bila tak balas. | C17: V/E | D17: ☐
A18: 3 | B18: Uji subsequent collection setelah tanggal neraca. | C18: A/V | D18: ☐
A19: 4 | B19: Re-perform model ECL/CKPN (PSAK 71); evaluasi asumsi. | C19: C/E | D19: ☐
A20: 5 | B20: Uji cut-off penjualan & retur; identifikasi pihak berelasi (PSAK 7). | C20: P&D | D20: ☐
A22: KESIMPULAN AREA
A23: Berdasarkan prosedur di atas, saldo akun area ini disajikan wajar dalam semua hal material sesuai kerangka pelaporan; salah saji teridentifikasi dicatat di 'AJE' & direkap di 'SAD'. [Tuliskan kesimpulan & isu terbuka spesifik.]
A26: Disusun oleh | B26: Dimas Raharja | C26: Tgl: | D26: ______ | E26: Direviu oleh | F26: Anindya Pramesti, CPA | G26: Tgl: | H26: ______
A27: Disetujui Partner | B27: Hartono Wijaya, CPA | C27: Tgl: | D27: ______

Sheet C - Persediaan
A1: ASSERIS · Kantor Akuntan Publik
A2: Registered Public Accountants · Izin Usaha KAP No. ___/KM.1/20__ · Anggota IAPI · www.asseris.co.id
A4: PT Sentosa Makmur Tbk — Tahun Buku Berakhir 31 Desember 2025
A5: LEAD SCHEDULE C — Persediaan
A6: Indeks KKA: C · Standar: SA 501 · Fase: 2 · Fieldwork | H6: ↩ Index
A7: Saldo per akun tertaut ke WTB. Program prosedur & kesimpulan area mengikuti SA/PSAK terkait.
A9: Kode | B9: Nama Akun | C9: Saldo TL | D9: Per Klien | E9: AJE | F9: Saldo Audit | G9: Saldo / PM | H9: Ref
A10: 1-1300 | B10: Persediaan | C10: =WTB!D13 -> 64550200000 | D10: =WTB!E13 -> 78904100000 | E10: =WTB!F13 -> -2340000000 | F10: =WTB!G13 -> 76564100000 | G10: =IF('P1 - Materialitas'!C16=0,0,ABS(F10)/'P1 - Materialitas'!C16) -> 47.319845 | H10: C-1
B11: Total area | C11: =SUM(C10) -> 64550200000 | D11: =SUM(D10) -> 78904100000 | E11: =SUM(E10) -> -2340000000 | F11: =SUM(F10) -> 76564100000 | G11: =IF('P1 - Materialitas'!C16=0,0,ABS(F11)/'P1 - Materialitas'!C16) -> 47.319845
A13: PROGRAM PROSEDUR AUDIT
A14: # | B14: Prosedur | C14: Asersi | D14: ✓ | E14: Hasil / Ref Bukti
A15: 1 | B15: Hadiri stock opname & test count dua arah (SA 501 — wajib). | C15: C/E/A | D15: ☐
A16: 2 | B16: Uji penilaian: metode konsisten & sesuai PSAK 14. | C16: V/E | D16: ☐
A17: 3 | B17: Uji NRV vs biaya; cadangan persediaan usang/rusak. | C17: A/V | D17: ☐
A18: 4 | B18: Uji cut-off penerimaan & pengeluaran barang. | C18: C/E | D18: ☐
A19: 5 | B19: Rekonsiliasi hasil opname ke catatan & buku besar. | C19: P&D | D19: ☐
A21: KESIMPULAN AREA
A22: Berdasarkan prosedur di atas, saldo akun area ini disajikan wajar dalam semua hal material sesuai kerangka pelaporan; salah saji teridentifikasi dicatat di 'AJE' & direkap di 'SAD'. [Tuliskan kesimpulan & isu terbuka spesifik.]
A25: Disusun oleh | B25: Dimas Raharja | C25: Tgl: | D25: ______ | E25: Direviu oleh | F25: Anindya Pramesti, CPA | G25: Tgl: | H25: ______
A26: Disetujui Partner | B26: Hartono Wijaya, CPA | C26: Tgl: | D26: ______

Sheet D - Aset Tetap & Takberwujud
A1: ASSERIS · Kantor Akuntan Publik
A2: Registered Public Accountants · Izin Usaha KAP No. ___/KM.1/20__ · Anggota IAPI · www.asseris.co.id
A4: PT Sentosa Makmur Tbk — Tahun Buku Berakhir 31 Desember 2025
A5: LEAD SCHEDULE D — Aset Tetap & Takberwujud
A6: Indeks KKA: D · Standar: SA 500 · PSAK 16/19 · Fase: 2 · Fieldwork | H6: ↩ Index
A7: Saldo per akun tertaut ke WTB. Program prosedur & kesimpulan area mengikuti SA/PSAK terkait.
A9: Kode | B9: Nama Akun | C9: Saldo TL | D9: Per Klien | E9: AJE | F9: Saldo Audit | G9: Saldo / PM | H9: Ref
A10: 1-1500 | B10: Biaya Dibayar di Muka | C10: =WTB!D15 -> 1780400000 | D10: =WTB!E15 -> 2104600000 | E10: =WTB!F15 -> 0 | F10: =WTB!G15 -> 2104600000 | G10: =IF('P1 - Materialitas'!C16=0,0,ABS(F10)/'P1 - Materialitas'!C16) -> 1.3007316 | H10: D-1
A11: 1-2100 | B11: Aset Tetap - Harga Perolehan | C11: =WTB!D16 -> 183209000000 | D11: =WTB!E16 -> 200339700000 | E11: =WTB!F16 -> 0 | F11: =WTB!G16 -> 200339700000 | G11: =IF('P1 - Materialitas'!C16=0,0,ABS(F11)/'P1 - Materialitas'!C16) -> 123.81839 | H11: D-2
A12: 1-2110 | B12: Akumulasi Penyusutan | C12: =WTB!D17 -> -50860000000 | D12: =WTB!E17 -> -57180000000 | E12: =WTB!F17 -> -1120000000 | F12: =WTB!G17 -> -58300000000 | G12: =IF('P1 - Materialitas'!C16=0,0,ABS(F12)/'P1 - Materialitas'!C16) -> 36.03186 | H12: D-3
A13: 1-2400 | B13: Aset Takberwujud - Harga Perolehan | C13: =WTB!D18 -> 8400000000 | D13: =WTB!E18 -> 9600000000 | E13: =WTB!F18 -> 0 | F13: =WTB!G18 -> 9600000000 | G13: =IF('P1 - Materialitas'!C16=0,0,ABS(F13)/'P1 - Materialitas'!C16) -> 5.9332051 | H13: D-4
A14: 1-2410 | B14: Akumulasi Amortisasi | C14: =WTB!D19 -> -3360000000 | D14: =WTB!E19 -> -4700000000 | E14: =WTB!F19 -> 0 | F14: =WTB!G19 -> -4700000000 | G14: =IF('P1 - Materialitas'!C16=0,0,ABS(F14)/'P1 - Materialitas'!C16) -> 2.9047983 | H14: D-5
B15: Total area | C15: =SUM(C10:C14) -> 139169400000 | D15: =SUM(D10:D14) -> 150164300000 | E15: =SUM(E10:E14) -> -1120000000 | F15: =SUM(F10:F14) -> 149044300000 | G15: =IF('P1 - Materialitas'!C16=0,0,ABS(F15)/'P1 - Materialitas'!C16) -> 92.115667
A17: PROGRAM PROSEDUR AUDIT
A18: # | B18: Prosedur | C18: Asersi | D18: ✓ | E18: Hasil / Ref Bukti
A19: 1 | B19: Susun & uji FAR (mutasi: awal, penambahan, pelepasan, akhir). | C19: C/E/A | D19: ☐
A20: 2 | B20: Vouching penambahan ke faktur/kontrak; uji kapitalisasi vs beban. | C20: V/E | D20: ☐
A21: 3 | B21: Uji pelepasan & gain/loss; konfirmasi kepemilikan/legalitas. | C21: A/V | D21: ☐
A22: 4 | B22: Re-compute penyusutan & amortisasi; konsistensi masa manfaat. | C22: C/E | D22: ☐
A23: 5 | B23: Telaah indikasi penurunan nilai (impairment). | C23: P&D | D23: ☐
A25: KESIMPULAN AREA
A26: Berdasarkan prosedur di atas, saldo akun area ini disajikan wajar dalam semua hal material sesuai kerangka pelaporan; salah saji teridentifikasi dicatat di 'AJE' & direkap di 'SAD'. [Tuliskan kesimpulan & isu terbuka spesifik.]
A29: Disusun oleh | B29: Dimas Raharja | C29: Tgl: | D29: ______ | E29: Direviu oleh | F29: Anindya Pramesti, CPA | G29: Tgl: | H29: ______
A30: Disetujui Partner | B30: Hartono Wijaya, CPA | C30: Tgl: | D30: ______

Sheet E - Sewa Hak-Guna PSAK 73
A1: ASSERIS · Kantor Akuntan Publik
A2: Registered Public Accountants · Izin Usaha KAP No. ___/KM.1/20__ · Anggota IAPI · www.asseris.co.id
A4: PT Sentosa Makmur Tbk — Tahun Buku Berakhir 31 Desember 2025
A5: LEAD SCHEDULE E — Sewa Hak-Guna PSAK 73
A6: Indeks KKA: E · Standar: SA 540 · PSAK 73 · Fase: 2 · Fieldwork | H6: ↩ Index
A7: Saldo per akun tertaut ke WTB. Program prosedur & kesimpulan area mengikuti SA/PSAK terkait.
A9: Kode | B9: Nama Akun | C9: Saldo TL | D9: Per Klien | E9: AJE | F9: Saldo Audit | G9: Saldo / PM | H9: Ref
A10: 1-2300 | B10: Aset Hak-Guna (PSAK 73) | C10: =WTB!D20 -> 0 | D10: =WTB!E20 -> 12640000000 | E10: =WTB!F20 -> 0 | F10: =WTB!G20 -> 12640000000 | G10: =IF('P1 - Materialitas'!C16=0,0,ABS(F10)/'P1 - Materialitas'!C16) -> 7.8120534 | H10: E-1
A11: 2-1500 | B11: Liabilitas Sewa - Jk. Pendek | C11: =WTB!D26 -> 0 | D11: =WTB!E26 -> -3180000000 | E11: =WTB!F26 -> 0 | F11: =WTB!G26 -> -3180000000 | G11: =IF('P1 - Materialitas'!C16=0,0,ABS(F11)/'P1 - Materialitas'!C16) -> 1.9653742 | H11: E-2
A12: 2-2200 | B12: Liabilitas Sewa - Jk. Panjang | C12: =WTB!D28 -> 0 | D12: =WTB!E28 -> -9620000000 | E12: =WTB!F28 -> 0 | F12: =WTB!G28 -> -9620000000 | G12: =IF('P1 - Materialitas'!C16=0,0,ABS(F12)/'P1 - Materialitas'!C16) -> 5.9455659 | H12: E-3
B13: Total area | C13: =SUM(C10:C12) -> 0 | D13: =SUM(D10:D12) -> -160000000 | E13: =SUM(E10:E12) -> 0 | F13: =SUM(F10:F12) -> -160000000 | G13: =IF('P1 - Materialitas'!C16=0,0,ABS(F13)/'P1 - Materialitas'!C16) -> 0.098886751
A15: PROGRAM PROSEDUR AUDIT
A16: # | B16: Prosedur | C16: Asersi | D16: ✓ | E16: Hasil / Ref Bukti
A17: 1 | B17: Inventarisasi kontrak sewa; identifikasi komponen sewa. | C17: C/E/A | D17: ☐
A18: 2 | B18: Re-compute aset hak-guna & liabilitas sewa pada pengakuan awal. | C18: V/E | D18: ☐
A19: 3 | B19: Uji tingkat diskonto (incremental borrowing rate). | C19: A/V | D19: ☐
A20: 4 | B20: Re-compute amortisasi ROU & beban bunga liabilitas sewa. | C20: C/E | D20: ☐
A21: 5 | B21: Uji klasifikasi jk pendek vs panjang & pengungkapan. | C21: P&D | D21: ☐
A23: KESIMPULAN AREA
A24: Berdasarkan prosedur di atas, saldo akun area ini disajikan wajar dalam semua hal material sesuai kerangka pelaporan; salah saji teridentifikasi dicatat di 'AJE' & direkap di 'SAD'. [Tuliskan kesimpulan & isu terbuka spesifik.]
A27: Disusun oleh | B27: Dimas Raharja | C27: Tgl: | D27: ______ | E27: Direviu oleh | F27: Anindya Pramesti, CPA | G27: Tgl: | H27: ______
A28: Disetujui Partner | B28: Hartono Wijaya, CPA | C28: Tgl: | D28: ______

Sheet F - Utang Usaha & Akrual
A1: ASSERIS · Kantor Akuntan Publik
A2: Registered Public Accountants · Izin Usaha KAP No. ___/KM.1/20__ · Anggota IAPI · www.asseris.co.id
A4: PT Sentosa Makmur Tbk — Tahun Buku Berakhir 31 Desember 2025
A5: LEAD SCHEDULE F — Utang Usaha & Akrual
A6: Indeks KKA: F · Standar: SA 505 · SUL · Fase: 2 · Fieldwork | H6: ↩ Index
A7: Saldo per akun tertaut ke WTB. Program prosedur & kesimpulan area mengikuti SA/PSAK terkait.
A9: Kode | B9: Nama Akun | C9: Saldo TL | D9: Per Klien | E9: AJE | F9: Saldo Audit | G9: Saldo / PM | H9: Ref
A10: 2-1100 | B10: Utang Usaha | C10: =WTB!D22 -> -38220700000 | D10: =WTB!E22 -> -44900300000 | E10: =WTB!F22 -> 0 | F10: =WTB!G22 -> -44900300000 | G10: =IF('P1 - Materialitas'!C16=0,0,ABS(F10)/'P1 - Materialitas'!C16) -> 27.75028 | H10: F-1
A11: 2-1300 | B11: Beban Akrual | C11: =WTB!D24 -> -6440200000 | D11: =WTB!E24 -> -8120900000 | E11: =WTB!F24 -> -980000000 | F11: =WTB!G24 -> -9100900000 | G11: =IF('P1 - Materialitas'!C16=0,0,ABS(F11)/'P1 - Materialitas'!C16) -> 5.6247402 | H11: F-2
B12: Total area | C12: =SUM(C10:C11) -> -44660900000 | D12: =SUM(D10:D11) -> -53021200000 | E12: =SUM(E10:E11) -> -980000000 | F12: =SUM(F10:F11) -> -54001200000 | G12: =IF('P1 - Materialitas'!C16=0,0,ABS(F12)/'P1 - Materialitas'!C16) -> 33.37502
A14: PROGRAM PROSEDUR AUDIT
A15: # | B15: Prosedur | C15: Asersi | D15: ✓ | E15: Hasil / Ref Bukti
A16: 1 | B16: Rekonsiliasi utang usaha ke statement pemasok. | C16: C/E/A | D16: ☐
A17: 2 | B17: Search for unrecorded liabilities (uji pembayaran pasca-neraca). | C17: V/E | D17: ☐
A18: 3 | B18: Konfirmasi saldo pemasok signifikan/bersaldo nol. | C18: A/V | D18: ☐
A19: 4 | B19: Uji kewajaran & dasar perhitungan akrual. | C19: C/E | D19: ☐
A20: 5 | B20: Identifikasi transaksi pihak berelasi. | C20: P&D | D20: ☐
A22: KESIMPULAN AREA
A23: Berdasarkan prosedur di atas, saldo akun area ini disajikan wajar dalam semua hal material sesuai kerangka pelaporan; salah saji teridentifikasi dicatat di 'AJE' & direkap di 'SAD'. [Tuliskan kesimpulan & isu terbuka spesifik.]
A26: Disusun oleh | B26: Dimas Raharja | C26: Tgl: | D26: ______ | E26: Direviu oleh | F26: Anindya Pramesti, CPA | G26: Tgl: | H26: ______
A27: Disetujui Partner | B27: Hartono Wijaya, CPA | C27: Tgl: | D27: ______

Sheet G - Utang Bank & Pinjaman
A1: ASSERIS · Kantor Akuntan Publik
A2: Registered Public Accountants · Izin Usaha KAP No. ___/KM.1/20__ · Anggota IAPI · www.asseris.co.id
A4: PT Sentosa Makmur Tbk — Tahun Buku Berakhir 31 Desember 2025
A5: LEAD SCHEDULE G — Utang Bank & Pinjaman
A6: Indeks KKA: G · Standar: SA 505 · Fase: 2 · Fieldwork | H6: ↩ Index
A7: Saldo per akun tertaut ke WTB. Program prosedur & kesimpulan area mengikuti SA/PSAK terkait.
A9: Kode | B9: Nama Akun | C9: Saldo TL | D9: Per Klien | E9: AJE | F9: Saldo Audit | G9: Saldo / PM | H9: Ref
A10: 2-1200 | B10: Utang Bank Jangka Pendek | C10: =WTB!D23 -> -25000000000 | D10: =WTB!E23 -> -31500000000 | E10: =WTB!F23 -> 0 | F10: =WTB!G23 -> -31500000000 | G10: =IF('P1 - Materialitas'!C16=0,0,ABS(F10)/'P1 - Materialitas'!C16) -> 19.468329 | H10: G-1
A11: 2-2100 | B11: Utang Bank Jangka Panjang | C11: =WTB!D27 -> -42000000000 | D11: =WTB!E27 -> -38500000000 | E11: =WTB!F27 -> 0 | F11: =WTB!G27 -> -38500000000 | G11: =IF('P1 - Materialitas'!C16=0,0,ABS(F11)/'P1 - Materialitas'!C16) -> 23.794625 | H11: G-2
B12: Total area | C12: =SUM(C10:C11) -> -67000000000 | D12: =SUM(D10:D11) -> -70000000000 | E12: =SUM(E10:E11) -> 0 | F12: =SUM(F10:F11) -> -70000000000 | G12: =IF('P1 - Materialitas'!C16=0,0,ABS(F12)/'P1 - Materialitas'!C16) -> 43.262954
A14: PROGRAM PROSEDUR AUDIT
A15: # | B15: Prosedur | C15: Asersi | D15: ✓ | E15: Hasil / Ref Bukti
A16: 1 | B16: Konfirmasi saldo, plafon, jaminan & bunga ke bank. | C16: C/E/A | D16: ☐
A17: 2 | B17: Uji kepatuhan covenant; nilai dampak bila terlampaui. | C17: V/E | D17: ☐
A18: 3 | B18: Re-compute akrual bunga & beban keuangan. | C18: A/V | D18: ☐
A19: 4 | B19: Uji klasifikasi jk pendek vs panjang (jatuh tempo). | C19: C/E | D19: ☐
A20: 5 | B20: Telaah perjanjian kredit untuk pembatasan/komitmen. | C20: P&D | D20: ☐
A22: KESIMPULAN AREA
A23: Berdasarkan prosedur di atas, saldo akun area ini disajikan wajar dalam semua hal material sesuai kerangka pelaporan; salah saji teridentifikasi dicatat di 'AJE' & direkap di 'SAD'. [Tuliskan kesimpulan & isu terbuka spesifik.]
A26: Disusun oleh | B26: Dimas Raharja | C26: Tgl: | D26: ______ | E26: Direviu oleh | F26: Anindya Pramesti, CPA | G26: Tgl: | H26: ______
A27: Disetujui Partner | B27: Hartono Wijaya, CPA | C27: Tgl: | D27: ______

Sheet H - Perpajakan
A1: ASSERIS · Kantor Akuntan Publik
A2: Registered Public Accountants · Izin Usaha KAP No. ___/KM.1/20__ · Anggota IAPI · www.asseris.co.id
A4: PT Sentosa Makmur Tbk — Tahun Buku Berakhir 31 Desember 2025
A5: LEAD SCHEDULE H — Perpajakan
A6: Indeks KKA: H · Standar: PSAK 46 · SA 250 · Fase: 2 · Fieldwork | H6: ↩ Index
A7: Saldo per akun tertaut ke WTB. Program prosedur & kesimpulan area mengikuti SA/PSAK terkait.
A9: Kode | B9: Nama Akun | C9: Saldo TL | D9: Per Klien | E9: AJE | F9: Saldo Audit | G9: Saldo / PM | H9: Ref
A10: 1-1400 | B10: Pajak Dibayar di Muka | C10: =WTB!D14 -> 3902100000 | D10: =WTB!E14 -> 4551800000 | E10: =WTB!F14 -> 0 | F10: =WTB!G14 -> 4551800000 | G10: =IF('P1 - Materialitas'!C16=0,0,ABS(F10)/'P1 - Materialitas'!C16) -> 2.8132045 | H10: H-1
A11: 1-2500 | B11: Aset Pajak Tangguhan | C11: =WTB!D21 -> 4110000000 | D11: =WTB!E21 -> 4980000000 | E11: =WTB!F21 -> 470000000 | F11: =WTB!G21 -> 5450000000 | G11: =IF('P1 - Materialitas'!C16=0,0,ABS(F11)/'P1 - Materialitas'!C16) -> 3.36833 | H11: H-2
A12: 2-1400 | B12: Utang Pajak | C12: =WTB!D25 -> -4980300000 | D12: =WTB!E25 -> -6220100000 | E12: =WTB!F25 -> 0 | F12: =WTB!G25 -> -6220100000 | G12: =IF('P1 - Materialitas'!C16=0,0,ABS(F12)/'P1 - Materialitas'!C16) -> 3.8442843 | H12: H-3
A13: 5-5100 | B13: Beban Pajak Penghasilan | C13: =WTB!D37 -> 9180000000 | D13: =WTB!E37 -> 11240000000 | E13: =WTB!F37 -> -470000000 | F13: =WTB!G37 -> 10770000000 | G13: =IF('P1 - Materialitas'!C16=0,0,ABS(F13)/'P1 - Materialitas'!C16) -> 6.6563145 | H13: H-4
B14: Total area | C14: =SUM(C10:C13) -> 12211800000 | D14: =SUM(D10:D13) -> 14551700000 | E14: =SUM(E10:E13) -> 0 | F14: =SUM(F10:F13) -> 14551700000 | G14: =IF('P1 - Materialitas'!C16=0,0,ABS(F14)/'P1 - Materialitas'!C16) -> 8.9935646
A16: PROGRAM PROSEDUR AUDIT
A17: # | B17: Prosedur | C17: Asersi | D17: ✓ | E17: Hasil / Ref Bukti
A18: 1 | B18: Rekonsiliasi fiskal laba akuntansi → laba kena pajak. | C18: C/E/A | D18: ☐
A19: 2 | B19: Tie-out ke SPT Tahunan & Masa; uji PPh badan terutang. | C19: V/E | D19: ☐
A20: 3 | B20: Re-compute aset/liabilitas pajak tangguhan (PSAK 46). | C20: A/V | D20: ☐
A21: 4 | B21: Telaah risiko sengketa pajak & ketentuan tidak pasti. | C21: C/E | D21: ☐
A22: 5 | B22: Uji transaksi & dokumentasi transfer pricing afiliasi. | C22: P&D | D22: ☐
A24: KESIMPULAN AREA
A25: Berdasarkan prosedur di atas, saldo akun area ini disajikan wajar dalam semua hal material sesuai kerangka pelaporan; salah saji teridentifikasi dicatat di 'AJE' & direkap di 'SAD'. [Tuliskan kesimpulan & isu terbuka spesifik.]
A28: Disusun oleh | B28: Dimas Raharja | C28: Tgl: | D28: ______ | E28: Direviu oleh | F28: Anindya Pramesti, CPA | G28: Tgl: | H28: ______
A29: Disetujui Partner | B29: Hartono Wijaya, CPA | C29: Tgl: | D29: ______

Sheet I - Imbalan Kerja
A1: ASSERIS · Kantor Akuntan Publik
A2: Registered Public Accountants · Izin Usaha KAP No. ___/KM.1/20__ · Anggota IAPI · www.asseris.co.id
A4: PT Sentosa Makmur Tbk — Tahun Buku Berakhir 31 Desember 2025
A5: LEAD SCHEDULE I — Imbalan Kerja
A6: Indeks KKA: I · Standar: SA 540 · PSAK 24 · Fase: 2 · Fieldwork | H6: ↩ Index
A7: Saldo per akun tertaut ke WTB. Program prosedur & kesimpulan area mengikuti SA/PSAK terkait.
A9: Kode | B9: Nama Akun | C9: Saldo TL | D9: Per Klien | E9: AJE | F9: Saldo Audit | G9: Saldo / PM | H9: Ref
A10: 2-2300 | B10: Liabilitas Imbalan Kerja | C10: =WTB!D29 -> -11220000000 | D10: =WTB!E29 -> -13080000000 | E10: =WTB!F29 -> 0 | F10: =WTB!G29 -> -13080000000 | G10: =IF('P1 - Materialitas'!C16=0,0,ABS(F10)/'P1 - Materialitas'!C16) -> 8.0839919 | H10: I-1
B11: Total area | C11: =SUM(C10) -> -11220000000 | D11: =SUM(D10) -> -13080000000 | E11: =SUM(E10) -> 0 | F11: =SUM(F10) -> -13080000000 | G11: =IF('P1 - Materialitas'!C16=0,0,ABS(F11)/'P1 - Materialitas'!C16) -> 8.0839919
A13: PROGRAM PROSEDUR AUDIT
A14: # | B14: Prosedur | C14: Asersi | D14: ✓ | E14: Hasil / Ref Bukti
A15: 1 | B15: Peroleh laporan aktuaris; evaluasi kompetensi & objektivitas. | C15: C/E/A | D15: ☐
A16: 2 | B16: Uji asumsi aktuarial (diskonto, kenaikan gaji, mortalitas). | C16: V/E | D16: ☐
A17: 3 | B17: Rekonsiliasi data karyawan ke aktuaris. | C17: A/V | D17: ☐
A18: 4 | B18: Uji pencatatan beban & OCI sesuai PSAK 24. | C18: C/E | D18: ☐
A19: 5 | B19: Telaah kecukupan pengungkapan. | C19: P&D | D19: ☐
A21: KESIMPULAN AREA
A22: Berdasarkan prosedur di atas, saldo akun area ini disajikan wajar dalam semua hal material sesuai kerangka pelaporan; salah saji teridentifikasi dicatat di 'AJE' & direkap di 'SAD'. [Tuliskan kesimpulan & isu terbuka spesifik.]
A25: Disusun oleh | B25: Dimas Raharja | C25: Tgl: | D25: ______ | E25: Direviu oleh | F25: Anindya Pramesti, CPA | G25: Tgl: | H25: ______
A26: Disetujui Partner | B26: Hartono Wijaya, CPA | C26: Tgl: | D26: ______

Sheet J - Ekuitas
A1: ASSERIS · Kantor Akuntan Publik
A2: Registered Public Accountants · Izin Usaha KAP No. ___/KM.1/20__ · Anggota IAPI · www.asseris.co.id
A4: PT Sentosa Makmur Tbk — Tahun Buku Berakhir 31 Desember 2025
A5: LEAD SCHEDULE J — Ekuitas
A6: Indeks KKA: J · Standar: SA 500 · Fase: 2 · Fieldwork | H6: ↩ Index
A7: Saldo per akun tertaut ke WTB. Program prosedur & kesimpulan area mengikuti SA/PSAK terkait.
A9: Kode | B9: Nama Akun | C9: Saldo TL | D9: Per Klien | E9: AJE | F9: Saldo Audit | G9: Saldo / PM | H9: Ref
A10: 3-1100 | B10: Modal Saham | C10: =WTB!D30 -> -60000000000 | D10: =WTB!E30 -> -60000000000 | E10: =WTB!F30 -> 0 | F10: =WTB!G30 -> -60000000000 | G10: =IF('P1 - Materialitas'!C16=0,0,ABS(F10)/'P1 - Materialitas'!C16) -> 37.082532 | H10: J-1
A11: 3-2100 | B11: Saldo Laba | C11: =WTB!D31 -> -82362900000 | D11: =WTB!E31 -> -100456600000 | E11: =WTB!F31 -> 0 | F11: =WTB!G31 -> -100456600000 | G11: =IF('P1 - Materialitas'!C16=0,0,ABS(F11)/'P1 - Materialitas'!C16) -> 62.086418 | H11: J-2
B12: Total area | C12: =SUM(C10:C11) -> -142362900000 | D12: =SUM(D10:D11) -> -160456600000 | E12: =SUM(E10:E11) -> 0 | F12: =SUM(F10:F11) -> -160456600000 | G12: =IF('P1 - Materialitas'!C16=0,0,ABS(F12)/'P1 - Materialitas'!C16) -> 99.16895
A14: PROGRAM PROSEDUR AUDIT
A15: # | B15: Prosedur | C15: Asersi | D15: ✓ | E15: Hasil / Ref Bukti
A16: 1 | B16: Cocokkan modal disetor ke akta & pengesahan Kemenkumham. | C16: C/E/A | D16: ☐
A17: 2 | B17: Uji mutasi saldo laba (laba berjalan, dividen). | C17: V/E | D17: ☐
A18: 3 | B18: Telusuri dividen ke notulen RUPS. | C18: A/V | D18: ☐
A19: 4 | B19: Identifikasi transaksi dengan pemegang saham (PSAK 7). | C19: C/E | D19: ☐
A20: 5 | B20: Uji penyajian komponen ekuitas lain (OCI). | C20: P&D | D20: ☐
A22: KESIMPULAN AREA
A23: Berdasarkan prosedur di atas, saldo akun area ini disajikan wajar dalam semua hal material sesuai kerangka pelaporan; salah saji teridentifikasi dicatat di 'AJE' & direkap di 'SAD'. [Tuliskan kesimpulan & isu terbuka spesifik.]
A26: Disusun oleh | B26: Dimas Raharja | C26: Tgl: | D26: ______ | E26: Direviu oleh | F26: Anindya Pramesti, CPA | G26: Tgl: | H26: ______
A27: Disetujui Partner | B27: Hartono Wijaya, CPA | C27: Tgl: | D27: ______

Sheet K - Pendapatan & Beban
A1: ASSERIS · Kantor Akuntan Publik
A2: Registered Public Accountants · Izin Usaha KAP No. ___/KM.1/20__ · Anggota IAPI · www.asseris.co.id
A4: PT Sentosa Makmur Tbk — Tahun Buku Berakhir 31 Desember 2025
A5: LEAD SCHEDULE K — Pendapatan & Beban
A6: Indeks KKA: K · Standar: SA 240 · SA 520 · PSAK 72 · Fase: 2 · Fieldwork | H6: ↩ Index
A7: Saldo per akun tertaut ke WTB. Program prosedur & kesimpulan area mengikuti SA/PSAK terkait.
A9: Kode | B9: Nama Akun | C9: Saldo TL | D9: Per Klien | E9: AJE | F9: Saldo Audit | G9: Saldo / PM | H9: Ref
A10: 4-1100 | B10: Penjualan Bersih | C10: =WTB!D32 -> -284500000000 | D10: =WTB!E32 -> -331900000000 | E10: =WTB!F32 -> 1850000000 | F10: =WTB!G32 -> -330050000000 | G10: =IF('P1 - Materialitas'!C16=0,0,ABS(F10)/'P1 - Materialitas'!C16) -> 203.98483 | H10: K-1
A11: 5-1100 | B11: Beban Pokok Penjualan | C11: =WTB!D33 -> 198420000000 | D11: =WTB!E33 -> 230140000000 | E11: =WTB!F33 -> 2340000000 | F11: =WTB!G33 -> 232480000000 | G11: =IF('P1 - Materialitas'!C16=0,0,ABS(F11)/'P1 - Materialitas'!C16) -> 143.68245 | H11: K-2
A12: 5-2100 | B12: Beban Penjualan | C12: =WTB!D34 -> 22180000000 | D12: =WTB!E34 -> 26440000000 | E12: =WTB!F34 -> 0 | F12: =WTB!G34 -> 26440000000 | G12: =IF('P1 - Materialitas'!C16=0,0,ABS(F12)/'P1 - Materialitas'!C16) -> 16.341036 | H12: K-3
A13: 5-3100 | B13: Beban Umum & Administrasi | C13: =WTB!D35 -> 31990000000 | D13: =WTB!E35 -> 36720000000 | E13: =WTB!F35 -> 2720000000 | F13: =WTB!G35 -> 39440000000 | G13: =IF('P1 - Materialitas'!C16=0,0,ABS(F13)/'P1 - Materialitas'!C16) -> 24.375584 | H13: K-4
A14: 5-4100 | B14: Beban Keuangan | C14: =WTB!D36 -> 7220000000 | D14: =WTB!E36 -> 8910000000 | E14: =WTB!F36 -> 0 | F14: =WTB!G36 -> 8910000000 | G14: =IF('P1 - Materialitas'!C16=0,0,ABS(F14)/'P1 - Materialitas'!C16) -> 5.506756 | H14: K-5
B15: Total area | C15: =SUM(C10:C14) -> -24690000000 | D15: =SUM(D10:D14) -> -29690000000 | E15: =SUM(E10:E14) -> 6910000000 | F15: =SUM(F10:F14) -> -22780000000 | G15: =IF('P1 - Materialitas'!C16=0,0,ABS(F15)/'P1 - Materialitas'!C16) -> 14.079001
A17: PROGRAM PROSEDUR AUDIT
A18: # | B18: Prosedur | C18: Asersi | D18: ✓ | E18: Hasil / Ref Bukti
A19: 1 | B19: Uji pengakuan pendapatan per PSAK 72 (5 langkah); cut-off ketat. | C19: C/E/A | D19: ☐
A20: 2 | B20: Uji jurnal manual & pendapatan tidak biasa (fraud — SA 240). | C20: V/E | D20: ☐
A21: 3 | B21: Prosedur analitis substantif beban vs tahun lalu & anggaran (SA 520). | C21: A/V | D21: ☐
A22: 4 | B22: Uji detail sampel beban; salah klasifikasi/kapitalisasi. | C22: C/E | D22: ☐
A23: 5 | B23: Identifikasi pihak berelasi & retur/diskon. | C23: P&D | D23: ☐
A25: KESIMPULAN AREA
A26: Berdasarkan prosedur di atas, saldo akun area ini disajikan wajar dalam semua hal material sesuai kerangka pelaporan; salah saji teridentifikasi dicatat di 'AJE' & direkap di 'SAD'. [Tuliskan kesimpulan & isu terbuka spesifik.]
A29: Disusun oleh | B29: Dimas Raharja | C29: Tgl: | D29: ______ | E29: Direviu oleh | F29: Anindya Pramesti, CPA | G29: Tgl: | H29: ______
A30: Disetujui Partner | B30: Hartono Wijaya, CPA | C30: Tgl: | D30: ______

Sheet AR - Analitis
A1: ASSERIS · Kantor Akuntan Publik
A2: Registered Public Accountants · Izin Usaha KAP No. ___/KM.1/20__ · Anggota IAPI · www.asseris.co.id
A4: PT Sentosa Makmur Tbk — Tahun Buku Berakhir 31 Desember 2025
A5: PROSEDUR ANALITIS SUBSTANTIF
A6: Indeks KKA: AR · Standar: SA 520 · Fase: 2 · Fieldwork | H6: ↩ Index
A7: Rasio & tren dari WTB (Saldo Audit vs TL). Selisih > ekspektasi diselidiki (SA 520).
A9: Indikator | B9: Tahun Ini | C9: Tahun Lalu | D9: Δ | E9: Δ % | F9: Penjelasan / Tindak Lanjut
A10: Penjualan Bersih (Rp) | B10: =ABS(WTB!G32) -> 330050000000 | C10: =ABS(WTB!D32) -> 284500000000 | D10: =B10-C10 -> 45550000000 | E10: =IF(C10=0,0,(B10-C10)/C10) -> 0.16010545
A11: Beban Pokok Penjualan (Rp) | B11: =WTB!G33 -> 232480000000 | C11: =WTB!D33 -> 198420000000 | D11: =B11-C11 -> 34060000000 | E11: =IF(C11=0,0,(B11-C11)/C11) -> 0.17165608
A12: Laba Kotor (Rp) | B12: =B10-B11 -> 97570000000 | C12: =C10-C11 -> 86080000000 | D12: =B12-C12 -> 11490000000 | E12: =IF(C12=0,0,(B12-C12)/C12) -> 0.13348048
A13: Marjin Laba Kotor | B13: =IF(B10=0,0,B12/B10) -> 0.29562188 | C13: =IF(C10=0,0,C12/C10) -> 0.30256591 | D13: =B13-C13 -> -0.0069440296
A14: Piutang Usaha neto (Rp) | B14: =WTB!G11+WTB!G12 -> 46872400000 | C14: =WTB!D11+WTB!D12 -> 40071900000 | D14: =B14-C14 -> 6800500000 | E14: =IF(C14=0,0,(B14-C14)/C14) -> 0.16970745
A15: Hari Penagihan (DSO) | B15: =IF(B10=0,0,B14/B10*365) -> 51.835861 | C15: =IF(C10=0,0,C14/C10*365) -> 51.410346 | D15: =B15-C15 -> 0.42551501 | E15: =IF(C15=0,0,(B15-C15)/C15) -> 0.0082768361
A16: Persediaan (Rp) | B16: =WTB!G13 -> 76564100000 | C16: =WTB!D13 -> 64550200000 | D16: =B16-C16 -> 12013900000 | E16: =IF(C16=0,0,(B16-C16)/C16) -> 0.18611716
A17: Hari Persediaan (DIO) | B17: =IF(B11=0,0,B16/B11*365) -> 120.20774 | C17: =IF(C11=0,0,C16/C11*365) -> 118.74218 | D17: =B17-C17 -> 1.4655665 | E17: =IF(C17=0,0,(B17-C17)/C17) -> 0.012342426
A19: Ekspektasi & ambang investigasi
A20: Selisih melebihi ambang (mis. > PM atau > 10% tanpa penjelasan bisnis) wajib diselidiki & didokumentasikan; kaitkan ke risiko P2 dan uji detail area terkait.

Sheet SMP - Sampling
A1: ASSERIS · Kantor Akuntan Publik
A2: Registered Public Accountants · Izin Usaha KAP No. ___/KM.1/20__ · Anggota IAPI · www.asseris.co.id
A4: PT Sentosa Makmur Tbk — Tahun Buku Berakhir 31 Desember 2025
A5: SAMPLING — MONETARY UNIT SAMPLING
A6: Indeks KKA: SMP · Standar: SA 530 · Fase: 2 · Fieldwork | H6: ↩ Index
A7: Ukuran sampel berbasis nilai (SA 530). Interval & n dihitung formula.
A9: Parameter | B9: Nilai | D9: Keterangan
A10: Populasi (nilai buku diuji, Rp) | B10: 51322400000 | D10: Mis. Piutang Usaha (WTB B)
A11: Tingkat keyakinan | B11: 0.95 | D11: Confidence level
A12: Faktor reliabilitas (R) | B12: 3 | D12: Tabel Poisson (0 deviasi)
A13: Tolerable Misstatement (Rp) | B13: ='P1 - Materialitas'!C16 -> 1618012500 | D13: Sama dengan Performance Materiality (P1)
A14: Expected Misstatement (Rp) | B14: 414000000 | D14: Estimasi salah saji
A15: Faktor ekspansi (EF) | B15: 1.6 | D15: Untuk expected misstatement
A17: Sampling interval (TM ÷ R) | B17: =B13/B12 -> 539337500 | D17: Setiap rupiah ke-n dipilih
A18: Ukuran sampel (n) | B18: =ROUNDUP((B10*B12)/(B13-B14*B15),0) -> 162 | D18: Rumus: (Populasi×R)/(TM − EM×EF)
A20: Item ≥ interval (high-value) diuji 100%. Hasil → proyeksikan salah saji ke 'SAD'.

Sheet JET - Jurnal
A1: ASSERIS · Kantor Akuntan Publik
A2: Registered Public Accountants · Izin Usaha KAP No. ___/KM.1/20__ · Anggota IAPI · www.asseris.co.id
A4: PT Sentosa Makmur Tbk — Tahun Buku Berakhir 31 Desember 2025
A5: JOURNAL ENTRY TESTING
A6: Indeks KKA: JET · Standar: SA 240 · Fase: 2 · Fieldwork | H6: ↩ Index
A7: Uji jurnal berisiko fraud (SA 240): manual, akhir periode, round-number, akun tak biasa.
A9: No Jurnal | B9: Tanggal | C9: Deskripsi | D9: Debit (Rp) | E9: Kredit (Rp) | F9: Pembuat | G9: Kriteria Risiko | H9: Status
A10: JV-1188 | B10: 31/12/2025 | C10: Pengakuan pendapatan akhir tahun | D10: 4250000000 | E10: 4250000000 | F10: Staf Acc | G10: Manual · akhir periode | H10: ☐ Uji
A11: JV-1190 | B11: 31/12/2025 | C11: Reklas beban ke aset (kapitalisasi) | D11: 1120000000 | E11: 1120000000 | F11: Manajer Keu | G11: Manual · akun tak biasa | H11: ☐ Uji
A12: JV-1201 | B12: 30/12/2025 | C12: Penyesuaian persediaan round number | D12: 2000000000 | E12: 2000000000 | F12: Staf Acc | G12: Round number | H12: ☐ Uji
A13: JV-1207 | B13: 31/12/2025 | C13: Jurnal balik pendapatan | D13: 1850000000 | E13: 1850000000 | F13: Manajer Keu | G13: Reversal · cut-off | H13: ☐ Uji
A14: JV-1215 | B14: 02/01/2026 | C14: Posting setelah tutup buku | D14: 980000000 | E14: 980000000 | F14: Staf Acc | G14: Post-closing | H14: ☐ Uji
A16: Kriteria seleksi (SA 240.32): jurnal ke akun kas/pendapatan, di luar jam kerja, personel tak lazim, deskripsi minim, atau membalik segera setelah periode. Tiap jurnal terpilih ditelusuri ke dokumen pendukung.

Sheet CONF - Konfirmasi
A1: ASSERIS · Kantor Akuntan Publik
A2: Registered Public Accountants · Izin Usaha KAP No. ___/KM.1/20__ · Anggota IAPI · www.asseris.co.id
A4: PT Sentosa Makmur Tbk — Tahun Buku Berakhir 31 Desember 2025
A5: LOG KONFIRMASI EKSTERNAL
A6: Indeks KKA: CONF · Standar: SA 505 · Fase: 2 · Fieldwork | H6: ↩ Index
A7: Register konfirmasi yang dikendalikan auditor: bank, piutang, utang, hukum (SA 505).
A9: No | B9: Pihak / Akun | C9: Jenis | D9: Tgl Kirim | E9: Tgl Terima | F9: Saldo Buku (Rp) | G9: Saldo Konfirm (Rp) | H9: Selisih / Tindak Lanjut
A10: 1 | B10: Bank ABC - Rekening Giro | C10: Positif | H10: Rekonsiliasi ke buku
A11: 2 | B11: PT Pelanggan Utama | C11: Positif | H11: Prosedur alternatif bila tak balas
A12: 3 | B12: PT Pemasok Sejahtera | C12: Positif
A13: 4 | B13: Konsultan Hukum | C13: Positif | H13: Litigasi/klaim (SA 501)
A19: Konfirmasi dikirim & diterima langsung oleh auditor (kendali penuh, SA 505). Non-respons konfirmasi positif → prosedur alternatif. Selisih diinvestigasi & dikaitkan ke lead area.

Sheet RPT - Pihak Berelasi
A1: ASSERIS · Kantor Akuntan Publik
A2: Registered Public Accountants · Izin Usaha KAP No. ___/KM.1/20__ · Anggota IAPI · www.asseris.co.id
A4: PT Sentosa Makmur Tbk — Tahun Buku Berakhir 31 Desember 2025
A5: DAFTAR PIHAK BERELASI & TRANSAKSI
A6: Indeks KKA: RPT · Standar: SA 550 · PSAK 7 · Fase: 2 · Fieldwork | G6: ↩ Index
A7: Identifikasi pihak berelasi, sifat & nilai transaksi, kewajaran & pengungkapan (SA 550 · PSAK 7).
A9: No | B9: Nama Pihak Berelasi | C9: Hubungan | D9: Sifat Transaksi | E9: Nilai (Rp) | F9: Arm's length? | G9: Pengungkapan (PSAK 7)
A10: 1 | B10: PT Induk Sentosa | C10: Entitas induk | D10: Pinjaman antar-perusahaan | F10: ☐ Ya ☐ Tidak | G10: ☐ Memadai
A11: 2 | B11: Manajemen kunci | C11: Personel manajemen kunci | D11: Kompensasi & bonus | F11: ☐ Ya ☐ Tidak | G11: ☐ Memadai
A12: 3 | B12: PT Afiliasi Distribusi | C12: Sepengendali | D12: Penjualan barang | F12: ☐ Ya ☐ Tidak | G12: ☐ Memadai
A17: Transaksi pihak berelasi berisiko fraud (SA 550). Uji kewajaran nilai (arm's length), otorisasi & kecukupan pengungkapan sesuai PSAK 7.

Sheet OB - Saldo Awal
A1: ASSERIS · Kantor Akuntan Publik
A2: Registered Public Accountants · Izin Usaha KAP No. ___/KM.1/20__ · Anggota IAPI · www.asseris.co.id
A4: PT Sentosa Makmur Tbk — Tahun Buku Berakhir 31 Desember 2025
A5: SALDO AWAL & ANGKA KOMPARATIF
A6: Indeks KKA: OB · Standar: SA 510 · SA 710 · Fase: 2 · Fieldwork | E6: ↩ Index
A7: Keyakinan atas saldo awal untuk perikatan tahun pertama/berlanjut (SA 510 · SA 710).
A9: No | B9: Uraian / Kriteria | C9: Ya/Ada | D9: Tidak | E9: Catatan / Ref WP
A10: 1 | B10: Saldo awal berasal dari LK auditan tahun lalu / diverifikasi memadai. | C10: ☐ | D10: ☐
A11: 2 | B11: Kebijakan akuntansi diterapkan konsisten antar-periode. | C11: ☐ | D11: ☐
A12: 3 | B12: Tidak ada salah saji saldo awal yang berdampak material tahun berjalan. | C12: ☐ | D12: ☐
A13: 4 | B13: Komunikasi & telaah kertas kerja auditor pendahulu (bila klien baru). | C13: ☐ | D13: ☐
A14: 5 | B14: Angka komparatif konsisten & tersaji sesuai (SA 710). | C14: ☐ | D14: ☐
A16: KESIMPULAN
A17: [Tuliskan kesimpulan, isu terbuka & tindak lanjut.]
A20: Disusun oleh | B20: Dimas Raharja | C20: Tgl: | D20: ______ | E20: Direviu oleh | F20: Anindya Pramesti, CPA | G20: Tgl: | H20: ______
A21: Disetujui Partner | B21: Hartono Wijaya, CPA | C21: Tgl: | D21: ______

Sheet SAD - Salah Saji
A1: ASSERIS · Kantor Akuntan Publik
A2: Registered Public Accountants · Izin Usaha KAP No. ___/KM.1/20__ · Anggota IAPI · www.asseris.co.id
A4: PT Sentosa Makmur Tbk — Tahun Buku Berakhir 31 Desember 2025
A5: RINGKASAN SALAH SAJI (SAD)
A6: Indeks KKA: SAD · Standar: SA 450 · Fase: 3 · Review | H6: ↩ Index
A7: Akumulasi salah saji corrected & uncorrected dievaluasi terhadap materialitas (SA 450).
A9: Ref | B9: Deskripsi | C9: Status | D9: Dampak Laba (Rp) | E9: Dampak Aset (Rp) | F9: Dampak Liab (Rp) | G9: Faktor | H9: WP
A10: M-01 | B10: Koreksi cut-off persediaan (AJE-01) | C10: Corrected | D10: -2340000000 | E10: -2340000000 | F10: 0 | G10: F | H10: C
A11: M-02 | B11: Tambahan CKPN piutang (AJE-02) | C11: Corrected | D11: -620000000 | E11: -620000000 | F11: 0 | G11: F | H11: B
A12: M-03 | B12: Pembalikan piutang fiktif (AJE-03) | C12: Corrected | D12: -1850000000 | E12: -1850000000 | F12: 0 | G12: F | H12: B
A13: M-04 | B13: Akrual bonus manajemen (AJE-04) | C13: Corrected | D13: -980000000 | E13: 0 | F13: 980000000 | G13: F | H13: F
A14: M-05 | B14: Penyusutan tambahan (AJE-05) | C14: Corrected | D14: -1120000000 | E14: -1120000000 | F14: 0 | G14: F | H14: D
A15: M-06 | B15: Estimasi beban garansi belum dicatat | C15: Uncorrected | D15: -310000000 | E15: 0 | F15: 310000000 | G15: E | H15: F
A16: M-07 | B16: Klasifikasi beban (judgmental) | C16: Uncorrected | D16: -150000000 | E16: 0 | F16: 0 | G16: J | H16: K
B17: Total Corrected (dampak laba) | D17: =SUMIF(C10:C16,"Corrected",D10:D16) -> -6910000000
B18: Total Uncorrected (dampak laba) | D18: =SUMIF(C10:C16,"Uncorrected",D10:D16) -> -460000000
A20: EVALUASI TERHADAP MATERIALITAS
B21: Total uncorrected (absolut) | D21: =ABS(D18) -> 460000000
B22: Overall Materiality (P1) | D22: ='P1 - Materialitas'!C14 -> 2489250000
B23: Uncorrected < OM ? | D23: =IF(D21<D22,"YA — tidak material","TIDAK — pertimbangkan modifikasi opini") -> YA — tidak material
A25: Kesimpulan: salah saji tidak dikoreksi, individual & agregat, [di bawah/melampaui] materialitas keseluruhan. Dampak opini dievaluasi di 'CONC'. Uncorrected dikomunikasikan ke TCWG (SA 260) & dimuat dalam MRL (SA 580).

Sheet RVW - Reviu & Penyelesaian
A1: ASSERIS · Kantor Akuntan Publik
